<mujoco model="zero_legged_robot">
    <include file="./common/visual.xml"/>
    <include file="./common/skybox.xml"/>
    <include file="./common/materials.xml"/>
    <asset>
        <material name="wheel" rgba=".3 .5 .7 .4"/>
        <material name="shaft" rgba=".7 .5 .3 1"/>
        <material name="weight" rgba=".8 .2 .2 1"/>
    </asset>
    <option timestep="0.002">
    </option>

    <worldbody>
        <light name="light" pos="0 0 2"/>
        <geom name="floor" size="2 2 .2" type="plane" material="grid"/>
        <camera name="lookat" mode="trackcom" target="wheel" pos="0 -1.0 0.1" xyaxes="1 0 0 0 0 1"/>
        <body name="wheel" pos="0 0 0.10">
            <joint armature="0" axis="1 0 0" damping="0" limited="false" name="rootx" pos="0 0 0.0" stiffness="0" type="slide"/>
            <joint armature="0" axis="0 0 1" damping="0" limited="false" name="rootz" pos="0 0 0.0" ref="0.0" stiffness="0" type="slide"/>
            <joint armature="0" axis="0 1 0" damping="0" limited="false" name="rooty" pos="0 0 0.0" stiffness="0" type="hinge"/>
            <geom name="wheel" material="wheel" type="cylinder" fromto="0 -.05 0 0 0.05 0" size="0.103" mass="0.8" friction="2.0"/>
            <geom name="shaft" material="shaft" type="cylinder" fromto="0 0 0 0 0 0.1" size="0.01" mass="0"/>
            <body name="weight" pos="0 0 0">
                <joint name="slider" type="slide" axis="0 0 1" damping="0.0" limited="true" range="-0.10 0.1" ref="0.00"/>
                <geom name="weight" material="weight" type="cylinder" fromto="0 0 -0.01 0 0 0.01" size="0.02" mass="0.2"/>
            </body>
        </body>
    </worldbody>

    <actuator>
        <motor name="slider" joint="slider" gear="1" ctrllimited="true" ctrlrange="-5.0 5.0" />
    </actuator>
</mujoco>
